<?xml version="1.0" encoding="UTF-8"?>
<!-- Generated by org.testng.reporters.JUnitReportReporter -->
<testsuite hostname="LAPTOP-GQ617UGP" failures="1" tests="7" name="LoginTestTesting" time="117.558" errors="0" timestamp="2024-10-11T22:11:48 IST" skipped="2">
  <testcase classname="LoginTestTesting" name="TC_loginWithEmailNull" time="17.440"/>
  <testcase classname="LoginTestTesting" name="TC_loginWithPasswordNull" time="10.450"/>
  <testcase classname="LoginTestTesting" name="TC_loginWithBothWrong" time="16.476"/>
  <testcase classname="LoginTestTesting" name="TC_loginWithWrongPassword" time="7.721"/>
  <testcase classname="LoginTestTesting" name="TC_successfulLogin" time="18.814">
    <failure message="Login was successful: https://srai.oyetest.com/login expected [true] but found [false]" type="java.lang.AssertionError">
      <![CDATA[java.lang.AssertionError: Login was successful: https://srai.oyetest.com/login expected [true] but found [false]
at org.testng.Assert.fail(Assert.java:111)
at org.testng.Assert.failNotEquals(Assert.java:1578)
at org.testng.Assert.assertTrue(Assert.java:57)
at LoginTestTesting.TC_successfulLogin(LoginTestTesting.java:133)
at java.base/jdk.internal.reflect.DirectMethodHandleAccessor.invoke(DirectMethodHandleAccessor.java:104)
at java.base/java.lang.reflect.Method.invoke(Method.java:578)
at org.testng.internal.invokers.MethodInvocationHelper.invokeMethod(MethodInvocationHelper.java:141)
at org.testng.internal.invokers.TestInvoker.invokeMethod(TestInvoker.java:686)
at org.testng.internal.invokers.TestInvoker.retryFailed(TestInvoker.java:269)
at org.testng.internal.invokers.MethodRunner.runInSequence(MethodRunner.java:76)
at org.testng.internal.invokers.TestInvoker$MethodInvocationAgent.invoke(TestInvoker.java:992)
at org.testng.internal.invokers.TestInvoker.invokeTestMethods(TestInvoker.java:203)
at org.testng.internal.invokers.TestMethodWorker.invokeTestMethods(TestMethodWorker.java:154)
at org.testng.internal.invokers.TestMethodWorker.run(TestMethodWorker.java:134)
at java.base/java.util.concurrent.Executors$RunnableAdapter.call(Executors.java:577)
at java.base/java.util.concurrent.FutureTask.run(FutureTask.java:317)
at org.testng.internal.thread.graph.TestNGFutureTask.run(TestNGFutureTask.java:22)
at java.base/java.util.concurrent.ThreadPoolExecutor.runWorker(ThreadPoolExecutor.java:1144)
at java.base/java.util.concurrent.ThreadPoolExecutor$Worker.run(ThreadPoolExecutor.java:642)
at java.base/java.lang.Thread.run(Thread.java:1589)
]]>
    </failure>
  </testcase> <!-- TC_successfulLogin -->
  <testcase classname="LoginTestTesting" name="TC_successfulLogin" time="29.139">
    <skipped/>
  </testcase> <!-- TC_successfulLogin -->
  <testcase classname="LoginTestTesting" name="TC_successfulLogin" time="17.518">
    <skipped/>
  </testcase> <!-- TC_successfulLogin -->
</testsuite> <!-- LoginTestTesting -->
